<?xml version="1.0" ?>
<!-- =================================================================================== -->
<!-- |    This document was autogenerated by xacro from /home/wego/ros_workspace/rrbot_ws/src/6DOF_rrbot_moveit_gazebo/gazebo_ros_demos/rrbot_description/urdf/rrbot.xacro | -->
<!-- |    EDITING THIS FILE BY HAND IS NOT RECOMMENDED                                 | -->
<!-- =================================================================================== -->
<!-- Revolute-Revolute Manipulator -->
<robot name="rrbot">
    <!-- Space btw top of beam and the each joint -->
    <!-- ros_control plugin -->
    <gazebo>
        <plugin filename="libgazebo_ros_control.so" name="gazebo_ros_control">
            <!--robotNamespace>/</robotNamespace-->
            <!--robotSimType>gazebo_ros_control/DefaultRobotHWSim</robotSimType-->
            <robotNamespace>/</robotNamespace>
        </plugin>
    </gazebo>
    <!-- Link1 -->
    <gazebo reference="base_link">
        <material>Gazebo/Black</material>
    </gazebo>
    <gazebo reference="link1">
        <mu1>0.2</mu1>
        <mu2>0.2</mu2>
        <material>Gazebo/Orange</material>
    </gazebo>
    <!-- Link2 -->
    <gazebo reference="link2">
        <mu1>0.2</mu1>
        <mu2>0.2</mu2>
        <material>Gazebo/Black</material>
    </gazebo>
    <!-- Link3 -->
    <gazebo reference="link3">
        <mu1>0.2</mu1>
        <mu2>0.2</mu2>
        <material>Gazebo/Orange</material>
    </gazebo>
    <gazebo reference="link4">
        <mu1>0.2</mu1>
        <mu2>0.2</mu2>
        <material>Gazebo/Black</material>
    </gazebo>
    <gazebo reference="link5">
        <mu1>0.2</mu1>
        <mu2>0.2</mu2>
        <material>Gazebo/Orange</material>
    </gazebo>
    <gazebo reference="link6">
        <mu1>0.2</mu1>
        <mu2>0.2</mu2>
        <material>Gazebo/Black</material>
    </gazebo>
    <material name="black">
        <color rgba="0.0 0.0 0.0 1.0" />
    </material>
    <material name="blue">
        <color rgba="0.0 0.0 0.8 1.0" />
    </material>
    <material name="green">
        <color rgba="0.0 0.8 0.0 1.0" />
    </material>
    <material name="grey">
        <color rgba="0.2 0.2 0.2 1.0" />
    </material>
    <material name="orange">
        <color rgba="1.0 0.4235294117647059 0.0392156862745098 1.0" />
    </material>
    <material name="brown">
        <color rgba="0.8705882352941177 0.8117647058823529 0.7647058823529411 1.0" />
    </material>
    <material name="red">
        <color rgba="0.8 0.0 0.0 1.0" />
    </material>
    <material name="white">
        <color rgba="1.0 1.0 1.0 1.0" />
    </material>
    <!-- Used for fixing robot to Gazebo 'base_link' -->
    <link name="world" />
    <joint name="fixed" type="fixed">
        <parent link="world" />
        <child link="base_link" />
    </joint>
    <!-- Base Link -->
    <link name="base_link">
        <collision>
            <origin rpy="0 0 0" xyz="0 0 0.05" />
            <geometry>
                <box size="0.1 0.1 0.1" />
            </geometry>
        </collision>
        <visual>
            <origin rpy="0 0 0" xyz="0 0 0.05" />
            <geometry>
                <box size="0.1 0.1 0.1" />
            </geometry>
            <material name="black" />
        </visual>
        <inertial>
            <origin rpy="0 0 0" xyz="0 0 0.05" />
            <mass value="0.5" />
            <inertia ixx="0.0008333333333333335" ixy="0.0" ixz="0.0" iyy="0.0008333333333333335" iyz="0.0" izz="0.0008333333333333335" />
        </inertial>
    </link>
    <joint name="joint0" type="continuous">
        <parent link="base_link" />
        <child link="link1" />
        <origin rpy="0 0 0" xyz="0 0 0.1" />
        <axis xyz="0 0 1" />
        <dynamics damping="0.7" />
    </joint>
    <link name="link1">
        <collision>
            <origin rpy="0 0 0" xyz="0 0 0.15" />
            <geometry>
                <box size="0.1 0.1 0.3" />
            </geometry>
        </collision>
        <visual>
            <origin rpy="0 0 0" xyz="0 0 0.15" />
            <geometry>
                <box size="0.1 0.1 0.3" />
            </geometry>
            <material name="orange" />
        </visual>
        <inertial>
            <origin rpy="0 0 0" xyz="0 0 0.15" />
            <mass value="0.5" />
            <inertia ixx="0.004166666666666667" ixy="0.0" ixz="0.0" iyy="0.004166666666666667" iyz="0.0" izz="0.0008333333333333335" />
        </inertial>
    </link>
    <joint name="joint1" type="continuous">
        <parent link="link1" />
        <child link="link2" />
        <origin rpy="0 0 0" xyz="0 0.1 0.25" />
        <axis xyz="0 1 0" />
        <dynamics damping="0.7" />
    </joint>
    <link name="link2">
        <collision>
            <origin rpy="0 0 0" xyz="0 0 0.45" />
            <geometry>
                <box size="0.1 0.1 1" />
            </geometry>
        </collision>
        <visual>
            <origin rpy="0 0 0" xyz="0 0 0.45" />
            <geometry>
                <box size="0.1 0.1 1" />
            </geometry>
            <material name="black" />
        </visual>
        <inertial>
            <origin rpy="0 0 0" xyz="0 0 0.45" />
            <mass value="0.5" />
            <inertia ixx="0.042083333333333334" ixy="0.0" ixz="0.0" iyy="0.042083333333333334" iyz="0.0" izz="0.0008333333333333335" />
        </inertial>
    </link>
    <joint name="joint2" type="continuous">
        <parent link="link2" />
        <child link="link3" />
        <origin rpy="0 0 0" xyz="0 -0.1 0.9" />
        <axis xyz="0 1 0" />
        <dynamics damping="0.7" />
    </joint>
    <link name="link3">
        <collision>
            <origin rpy="0 0 0" xyz="0 0 0.45" />
            <geometry>
                <box size="0.1 0.1 1" />
            </geometry>
        </collision>
        <visual>
            <origin rpy="0 0 0" xyz="0 0 0.45" />
            <geometry>
                <box size="0.1 0.1 1" />
            </geometry>
            <material name="orange" />
        </visual>
        <inertial>
            <origin rpy="0 0 0" xyz="0 0 0.45" />
            <mass value="0.5" />
            <inertia ixx="0.042083333333333334" ixy="0.0" ixz="0.0" iyy="0.042083333333333334" iyz="0.0" izz="0.0008333333333333335" />
        </inertial>
    </link>
    <joint name="joint3" type="continuous">
        <parent link="link3" />
        <child link="link4" />
        <origin rpy="0 0 0" xyz="0 0.1 0.9" />
        <axis xyz="0 1 0" />
        <dynamics damping="0.7" />
    </joint>
    <!-- Top Link -->
    <link name="link4">
        <collision>
            <origin rpy="0 0 0" xyz="0 0 0.09999999999999999" />
            <geometry>
                <box size="0.1 0.1 0.3" />
            </geometry>
        </collision>
        <visual>
            <origin rpy="0 0 0" xyz="0 0 0.09999999999999999" />
            <geometry>
                <box size="0.1 0.1 0.3" />
            </geometry>
            <material name="orange" />
        </visual>
        <inertial>
            <origin rpy="0 0 0" xyz="0 0 0.09999999999999999" />
            <mass value="0.5" />
            <inertia ixx="0.004166666666666667" ixy="0.0" ixz="0.0" iyy="0.004166666666666667" iyz="0.0" izz="0.0008333333333333335" />
        </inertial>
    </link>
    <joint name="joint4" type="continuous">
        <parent link="link4" />
        <child link="link5" />
        <origin rpy="0 0 0" xyz="0.1 0 0.19999999999999998" />
        <axis xyz="1 0 0" />
        <dynamics damping="0.7" />
    </joint>
    <!-- Top Link -->
    <link name="link5">
        <collision>
            <origin rpy="0 0 0" xyz="0 0 0.09999999999999999" />
            <geometry>
                <box size="0.1 0.1 0.3" />
            </geometry>
        </collision>
        <visual>
            <origin rpy="0 0 0" xyz="0 0 0.09999999999999999" />
            <geometry>
                <box size="0.1 0.1 0.3" />
            </geometry>
            <material name="black" />
        </visual>
        <inertial>
            <origin rpy="0 0 0" xyz="0 0 0.09999999999999999" />
            <mass value="0.5" />
            <inertia ixx="0.004166666666666667" ixy="0.0" ixz="0.0" iyy="0.004166666666666667" iyz="0.0" izz="0.0008333333333333335" />
        </inertial>
    </link>
    <joint name="joint5" type="continuous">
        <parent link="link5" />
        <child link="link6" />
        <origin rpy="0 0 0" xyz="0 0 0.25" />
        <axis xyz="0 0 1" />
        <dynamics damping="0.7" />
    </joint>
    <!-- Top Link -->
    <link name="link6">
        <collision>
            <origin rpy="0 0 0" xyz="0 0 0.05" />
            <geometry>
                <box size="0.1 0.1 0.1" />
            </geometry>
        </collision>
        <visual>
            <origin rpy="0 0 0" xyz="0 0 0.05" />
            <geometry>
                <box size="0.1 0.1 0.1" />
            </geometry>
            <material name="black" />
        </visual>
        <inertial>
            <origin rpy="0 0 0" xyz="0 0 0.1" />
            <mass value="0.5" />
            <inertia ixx="0.0008333333333333335" ixy="0.0" ixz="0.0" iyy="0.0008333333333333335" iyz="0.0" izz="0.0008333333333333335" />
        </inertial>
    </link>
    <transmission name="tran0">
        <type>transmission_interface/SimpleTransmission</type>
        <joint name="joint0">
            <hardwareInterface>hardware_interface/PositionJointInterface</hardwareInterface>
        </joint>
        <actuator name="motor0">
            <hardwareInterface>hardware_interface/PositionJointInterface</hardwareInterface>
            <mechanicalReduction>1</mechanicalReduction>
        </actuator>
    </transmission>
    <transmission name="tran1">
        <type>transmission_interface/SimpleTransmission</type>
        <joint name="joint1">
            <hardwareInterface>hardware_interface/PositionJointInterface</hardwareInterface>
        </joint>
        <actuator name="motor1">
            <hardwareInterface>hardware_interface/PositionJointInterface</hardwareInterface>
            <mechanicalReduction>1</mechanicalReduction>
        </actuator>
    </transmission>
    <transmission name="tran2">
        <type>transmission_interface/SimpleTransmission</type>
        <joint name="joint2">
            <hardwareInterface>hardware_interface/PositionJointInterface</hardwareInterface>
        </joint>
        <actuator name="motor2">
            <hardwareInterface>hardware_interface/PositionJointInterface</hardwareInterface>
            <mechanicalReduction>1</mechanicalReduction>
        </actuator>
    </transmission>
    <transmission name="tran3">
        <type>transmission_interface/SimpleTransmission</type>
        <joint name="joint3">
            <hardwareInterface>hardware_interface/PositionJointInterface</hardwareInterface>
        </joint>
        <actuator name="motor3">
            <hardwareInterface>hardware_interface/PositionJointInterface</hardwareInterface>
            <mechanicalReduction>1</mechanicalReduction>
        </actuator>
    </transmission>
    <transmission name="tran4">
        <type>transmission_interface/SimpleTransmission</type>
        <joint name="joint4">
            <hardwareInterface>hardware_interface/PositionJointInterface</hardwareInterface>
        </joint>
        <actuator name="motor4">
            <hardwareInterface>hardware_interface/PositionJointInterface</hardwareInterface>
            <mechanicalReduction>1</mechanicalReduction>
        </actuator>
    </transmission>
    <transmission name="tran5">
        <type>transmission_interface/SimpleTransmission</type>
        <joint name="joint5">
            <hardwareInterface>hardware_interface/PositionJointInterface</hardwareInterface>
        </joint>
        <actuator name="motor5">
            <hardwareInterface>hardware_interface/PositionJointInterface</hardwareInterface>
            <mechanicalReduction>1</mechanicalReduction>
        </actuator>
    </transmission>
    <!--transmission name="tran0">
    <type>transmission_interface/SimpleTransmission</type>
    <joint name="joint0">
      <hardwareInterface>hardware_interface/EffortJointInterface</hardwareInterface>
    </joint>
    <actuator name="motor0">
      <hardwareInterface>hardware_interface/EffortJointInterface</hardwareInterface>
      <mechanicalReduction>1</mechanicalReduction>
    </actuator>
  </transmission>

  <transmission name="tran1">
    <type>transmission_interface/SimpleTransmission</type>
    <joint name="joint1">
      <hardwareInterface>hardware_interface/EffortJointInterface</hardwareInterface>
    </joint>
    <actuator name="motor1">
      <hardwareInterface>hardware_interface/EffortJointInterface</hardwareInterface>
      <mechanicalReduction>1</mechanicalReduction>
    </actuator>
  </transmission>

  <transmission name="tran2">
    <type>transmission_interface/SimpleTransmission</type>
    <joint name="joint2">
      <hardwareInterface>hardware_interface/EffortJointInterface</hardwareInterface>
    </joint>
    <actuator name="motor2">
      <hardwareInterface>hardware_interface/EffortJointInterface</hardwareInterface>
      <mechanicalReduction>1</mechanicalReduction>
    </actuator>
  </transmission>

  <transmission name="tran3">
    <type>transmission_interface/SimpleTransmission</type>
    <joint name="joint3">
      <hardwareInterface>hardware_interface/EffortJointInterface</hardwareInterface>
    </joint>
    <actuator name="motor3">
      <hardwareInterface>hardware_interface/EffortJointInterface</hardwareInterface>
      <mechanicalReduction>1</mechanicalReduction>
    </actuator>
  </transmission>

  <transmission name="tran4">
    <type>transmission_interface/SimpleTransmission</type>
    <joint name="joint4">
      <hardwareInterface>hardware_interface/EffortJointInterface</hardwareInterface>
    </joint>
    <actuator name="motor4">
      <hardwareInterface>hardware_interface/EffortJointInterface</hardwareInterface>
      <mechanicalReduction>1</mechanicalReduction>
    </actuator>
  </transmission>

  <transmission name="tran5">
    <type>transmission_interface/SimpleTransmission</type>
    <joint name="joint5">
      <hardwareInterface>hardware_interface/EffortJointInterface</hardwareInterface>
    </joint>
    <actuator name="motor5">
      <hardwareInterface>hardware_interface/EffortJointInterface</hardwareInterface>
      <mechanicalReduction>1</mechanicalReduction>
    </actuator>
  </transmission-->
</robot>

